<?xml version="1.0" encoding="UTF-8"?>
<testng-results skipped="0" failed="1" ignored="0" total="4" passed="3">
  <reporter-output>
  </reporter-output>
  <suite name="Test" duration-ms="94" started-at="2021-08-09T20:00:20 EEST" finished-at="2021-08-09T20:00:20 EEST">
    <groups>
    </groups>
    <test name="Command line test" duration-ms="94" started-at="2021-08-09T20:00:20 EEST" finished-at="2021-08-09T20:00:20 EEST">
      <class name="Test">
        <test-method status="PASS" signature="setUpUser()[pri:0, instance:Test@5b275dab]" name="setUpUser" is-config="true" duration-ms="16" started-at="2021-08-09T20:00:20 EEST" finished-at="2021-08-09T20:00:20 EEST">
          <reporter-output>
          </reporter-output>
        </test-method> <!-- setUpUser -->
        <test-method status="PASS" signature="testIsRegistered()[pri:0, instance:Test@5b275dab]" name="testIsRegistered" duration-ms="0" started-at="2021-08-09T20:00:20 EEST" finished-at="2021-08-09T20:00:20 EEST">
          <reporter-output>
          </reporter-output>
        </test-method> <!-- testIsRegistered -->
        <test-method status="PASS" signature="testSumm()[pri:0, instance:Test@5b275dab]" name="testSumm" duration-ms="0" started-at="2021-08-09T20:00:20 EEST" finished-at="2021-08-09T20:00:20 EEST">
          <reporter-output>
          </reporter-output>
        </test-method> <!-- testSumm -->
        <test-method status="PASS" signature="testUserName()[pri:0, instance:Test@5b275dab]" name="testUserName" duration-ms="0" started-at="2021-08-09T20:00:20 EEST" finished-at="2021-08-09T20:00:20 EEST">
          <reporter-output>
          </reporter-output>
        </test-method> <!-- testUserName -->
        <test-method status="FAIL" signature="testUserAge()[pri:0, instance:Test@5b275dab]" name="testUserAge" duration-ms="0" started-at="2021-08-09T20:00:20 EEST" finished-at="2021-08-09T20:00:20 EEST">
          <exception class="java.lang.AssertionError">
            <message>
              <![CDATA[Something wrong with test data expected [31] but found [30]]]>
            </message>
            <full-stacktrace>
              <![CDATA[java.lang.AssertionError: Something wrong with test data expected [31] but found [30]
at org.testng.Assert.fail(Assert.java:97)
at org.testng.Assert.assertEqualsImpl(Assert.java:136)
at org.testng.Assert.assertEquals(Assert.java:118)
at org.testng.Assert.assertEquals(Assert.java:839)
at Test.testUserAge(Test.java:31)
at sun.reflect.NativeMethodAccessorImpl.invoke0(Native Method)
at sun.reflect.NativeMethodAccessorImpl.invoke(NativeMethodAccessorImpl.java:62)
at sun.reflect.DelegatingMethodAccessorImpl.invoke(DelegatingMethodAccessorImpl.java:43)
at java.lang.reflect.Method.invoke(Method.java:498)
at org.testng.internal.MethodInvocationHelper.invokeMethod(MethodInvocationHelper.java:134)
at org.testng.internal.TestInvoker.invokeMethod(TestInvoker.java:597)
at org.testng.internal.TestInvoker.invokeTestMethod(TestInvoker.java:173)
at org.testng.internal.MethodRunner.runInSequence(MethodRunner.java:46)
at org.testng.internal.TestInvoker$MethodInvocationAgent.invoke(TestInvoker.java:816)
at org.testng.internal.TestInvoker.invokeTestMethods(TestInvoker.java:146)
at org.testng.internal.TestMethodWorker.invokeTestMethods(TestMethodWorker.java:146)
at org.testng.internal.TestMethodWorker.run(TestMethodWorker.java:128)
at java.util.ArrayList.forEach(ArrayList.java:1259)
at org.testng.TestRunner.privateRun(TestRunner.java:766)
at org.testng.TestRunner.run(TestRunner.java:587)
at org.testng.SuiteRunner.runTest(SuiteRunner.java:384)
at org.testng.SuiteRunner.runSequentially(SuiteRunner.java:378)
at org.testng.SuiteRunner.privateRun(SuiteRunner.java:337)
at org.testng.SuiteRunner.run(SuiteRunner.java:286)
at org.testng.SuiteRunnerWorker.runSuite(SuiteRunnerWorker.java:53)
at org.testng.SuiteRunnerWorker.run(SuiteRunnerWorker.java:96)
at org.testng.TestNG.runSuitesSequentially(TestNG.java:1187)
at org.testng.TestNG.runSuitesLocally(TestNG.java:1109)
at org.testng.TestNG.runSuites(TestNG.java:1039)
at org.testng.TestNG.run(TestNG.java:1007)
at org.apache.maven.surefire.testng.TestNGExecutor.run(TestNGExecutor.java:77)
at org.apache.maven.surefire.testng.TestNGDirectoryTestSuite.execute(TestNGDirectoryTestSuite.java:110)
at org.apache.maven.surefire.testng.TestNGProvider.invoke(TestNGProvider.java:106)
at sun.reflect.NativeMethodAccessorImpl.invoke0(Native Method)
at sun.reflect.NativeMethodAccessorImpl.invoke(NativeMethodAccessorImpl.java:62)
at sun.reflect.DelegatingMethodAccessorImpl.invoke(DelegatingMethodAccessorImpl.java:43)
at java.lang.reflect.Method.invoke(Method.java:498)
at org.apache.maven.surefire.util.ReflectionUtils.invokeMethodWithArray(ReflectionUtils.java:189)
at org.apache.maven.surefire.booter.ProviderFactory$ProviderProxy.invoke(ProviderFactory.java:165)
at org.apache.maven.surefire.booter.ProviderFactory.invokeProvider(ProviderFactory.java:85)
at org.apache.maven.surefire.booter.ForkedBooter.runSuitesInProcess(ForkedBooter.java:115)
at org.apache.maven.surefire.booter.ForkedBooter.main(ForkedBooter.java:75)
]]>
            </full-stacktrace>
          </exception> <!-- java.lang.AssertionError -->
          <reporter-output>
          </reporter-output>
        </test-method> <!-- testUserAge -->
        <test-method status="PASS" signature="cleanUp()[pri:0, instance:Test@5b275dab]" name="cleanUp" is-config="true" duration-ms="0" started-at="2021-08-09T20:00:20 EEST" finished-at="2021-08-09T20:00:20 EEST">
          <reporter-output>
          </reporter-output>
        </test-method> <!-- cleanUp -->
      </class> <!-- Test -->
    </test> <!-- Command line test -->
  </suite> <!-- Test -->
</testng-results>
